Workbook

Sheet DASHBOARD
B1: ISOTANK- ACID SUMMARY DASHBOARD
B3: TOTAL PRONTO (KG) | F3: TOTAL ACTUAL QTY Isotank | J3: TOTAL VARIANCE (KG) | N3: TOTAL ACTIVE ISOTANKS IN SYSTEM | R3: Noted : Waiting GR 1 PO Isotank
B4: 452540 | F4: =SUM('ACID & ESCAID STATUS '!E131:E153) -> 498260 | J4: =F4-B4 -> 45720 | N4: =T27 -> 84
B5: =CONCATENATE(ROUNDDOWN(B4/22000.5,0)," ISOTANK") -> 20 ISOTANK | F5: =CONCATENATE(ROUNDDOWN(F4/22000.5,0)," ISOTANK") -> 22 ISOTANK | J5: =CONCATENATE(ROUNDDOWN(J4/22000.5,0)," ISOTANK") -> 2 ISOTANK
B9: FORECAST ACID JUN '26
B10: Vendor | C10: Forecast ( Kg ) | D10: Price / Kg ( IDR ) | E10: Qty First PO Jun'26 | F10: On Site | H10: Inbound Koe - Wtr | J10: Inbound Sub - Koe | L10: Inbound Hub Sub | N10: Outbound Isotank | P10: Vendor PO Jun'26 | Q10: Difference | R10: Total PO May'26 | T10: Total Isotank Rotation
F11: Empty | G11: Full | H11: Qty Isotank | I11: Qty (Kg) | J11: Qty Isotank | K11: Qty ( Kg ) | L11: Qty Isotank | M11: Qty ( Kg ) | N11: KOE | O11: HUB | P11: has Supplied (Kg) | Q11: Qty ( Kg ) | R11: Qty Isotank | S11: Qty ( Kg )
B12: ROLIMEX | C12: 200000 | E12: =SUMIFS('SUM ISOTANK'!G:G, 'SUM ISOTANK'!B:B, "SOC ROLIMEX", 'SUM ISOTANK'!H:H, ">="&DATE(2026,7,1), 'SUM ISOTANK'!H:H, "<="&DATE(2026,7,31)) -> 92000 | F12: =IFERROR(GETPIVOTDATA("Count of TANK ID",'SUM ISOTANK'!$L$1,"Vendor","SOC ROLIMEX","STATUS","EMPTY","LOCATION","WAREHOUSE"),0) + IFERROR(GETPIVOTDATA("Count of TANK ID",'SUM ISOTANK'!$L$1,"Vendor","SOC ROLIMEX","STATUS","EMPTY","LOCATION","25KT"),0) -> 4 | G12: =IFERROR(GETPIVOTDATA("Count of TANK ID",'SUM ISOTANK'!$L$1,"Vendor","SOC ROLIMEX","STATUS","FULL","LOCATION","WAREHOUSE"),0) + IFERROR(GETPIVOTDATA("Count of TANK ID",'SUM ISOTANK'!$L$1,"Vendor","SOC ROLIMEX","STATUS","FULL","LOCATION","25KT"),0)+IFERROR(GETPIVOTDATA("Count of TANK ID",'SUM ISOTANK'!$L$1,"Vendor","SOC ROLIMEX","STATUS","INSTALL","LOCATION","25KT"),0)+IFERROR(GETPIVOTDATA("Count of TANK ID",'SUM ISOTANK'!$L$1,"Vendor","SOC ROLIMEX","STATUS","INSTALL","LOCATION","WAREHOUSE"),0) -> 2 | H12: =GETPIVOTDATA("Count of TANK ID",'SUM ISOTANK'!$L$1,"Vendor","SOC ROLIMEX","STATUS","FULL","LOCATION","INBOUND- KOE WTR") -> 11 | I12: =GETPIVOTDATA("Sum of Qty PO",'SUM ISOTANK'!$L$1,"Vendor","SOC ROLIMEX","STATUS","FULL","LOCATION","INBOUND- KOE WTR") -> 220980 | J12: =GETPIVOTDATA("Count of TANK ID",'SUM ISOTANK'!$L$1,"Vendor","SOC ROLIMEX","STATUS","FULL","LOCATION","INBOUND - SUB KOE") -> 2 | K12: =IFERROR(GETPIVOTDATA("Sum of Qty PO",'SUM ISOTANK'!$L$1,"Vendor","SOC ROLIMEX","STATUS","FULL","LOCATION","INBOUND - SUB KOE"),0) -> 40510 | L12: =IFERROR(GETPIVOTDATA("Count of TANK ID",#REF!,"Vendor","SOC ROLIMEX","STATUS","FULL","LOCATION","INBOUND - HUB SUB"), 0) -> 0 | M12: =IFERROR(GETPIVOTDATA("Sum of Qty PO",'SUM ISOTANK'!$L$1,"Vendor","SOC ROLIMEX","STATUS","FULL","LOCATION","INBOUND - HUB SUB"), 0) -> 0 | N12: 0 | O12: 2 | P12: =SUM(M12,K12,I12) -> 261490 | Q12: =SUM(M12,K12,I12)-E12 -> 169490 | T12: =SUM(F12,G12,H12,J12,L12,N12,O12) -> 21
B13: DWIJAYA | C13: 250000 | D13: 12500 | E13: 250000 | F13: =IFERROR(GETPIVOTDATA("Count of TANK ID",'SUM ISOTANK'!$L$1,"Vendor","SOC DJE","STATUS","EMPTY","LOCATION","WAREHOUSE"),0) + IFERROR(GETPIVOTDATA("Count of TANK ID",'SUM ISOTANK'!$L$1,"Vendor","SOC DJE","STATUS","EMPTY","LOCATION","25KT"),0) -> 6 | G13: =IFERROR(GETPIVOTDATA("Count of TANK ID",'SUM ISOTANK'!$L$1,"Vendor","SOC DJE","STATUS","FULL","LOCATION","WAREHOUSE"),0) + IFERROR(GETPIVOTDATA("Count of TANK ID",'SUM ISOTANK'!$L$1,"Vendor","SOC DJE","STATUS","FULL","LOCATION","25KT"),0)+IFERROR(GETPIVOTDATA("Count of TANK ID",'SUM ISOTANK'!$L$1,"Vendor","SOC DJE","STATUS","INSTALL","LOCATION","25KT"),0)+IFERROR(GETPIVOTDATA("Count of TANK ID",'SUM ISOTANK'!$L$1,"Vendor","SOC DJE","STATUS","INSTALL","LOCATION","WAREHOUSE"),0) -> 9 | H13: =GETPIVOTDATA("Count of TANK ID",'SUM ISOTANK'!$L$1,"Vendor","SOC DJE","STATUS","FULL","LOCATION","INBOUND- KOE WTR") -> 8 | I13: =IFERROR(GETPIVOTDATA("Sum of Qty PO",'SUM ISOTANK'!$L$1,"Vendor","SOC DJE","STATUS","FULL","LOCATION","INBOUND- KOE WTR"), 0) -> 168440 | J13: =GETPIVOTDATA("Count of TANK ID",'SUM ISOTANK'!$L$1,"Vendor","SOC DJE","STATUS","FULL","LOCATION","INBOUND - SUB KOE") -> 2 | K13: =IFERROR(GETPIVOTDATA("Sum of Qty PO",'SUM ISOTANK'!$L$1,"Vendor","SOC DJE","STATUS","FULL","LOCATION","INBOUND - SUB KOE"),0) -> 41930 | L13: =IFERROR(GETPIVOTDATA("Count of TANK ID",#REF!,"Vendor","SOC DJE","STATUS","FULL","LOCATION","INBOUND - HUB SUB"), 0) -> 0 | M13: =IFERROR(GETPIVOTDATA("Sum of Qty PO",'SUM ISOTANK'!$L$1,"Vendor","SOC DJE","STATUS","FULL","LOCATION","INBOUND - HUB SUB"), 0) -> 0 | N13: 0 | O13: 0 | P13: =SUM(M13,K13,I13) -> 210370 | Q13: =SUM(M13,K13,I13)-E13 -> -39630 | R13: 5 | S13: 103620 | T13: =SUM(F13,G13,H13,J13,L13,N13,O13) -> 25
B14: ENERGI JAYA INOVASI PT | C14: 200000 | E14: 200000 | F14: =IFERROR(GETPIVOTDATA("Count of TANK ID",'SUM ISOTANK'!$L$1,"Vendor","ENERGI JAYA INOVASI PT","STATUS","EMPTY","LOCATION","WAREHOUSE"),0) + IFERROR(GETPIVOTDATA("Count of TANK ID",'SUM ISOTANK'!$L$1,"Vendor","ENERGI JAYA INOVASI PT","STATUS","EMPTY","LOCATION","25KT"),0) -> 0 | G14: =IFERROR(GETPIVOTDATA("Count of TANK ID",'SUM ISOTANK'!$L$1,"Vendor","ENERGI JAYA INOVASI, PT","STATUS","FULL","LOCATION","WAREHOUSE"),0) + IFERROR(GETPIVOTDATA("Count of TANK ID",'SUM ISOTANK'!$L$1,"Vendor","ENERGI JAYA INOVASI, PT","STATUS","FULL","LOCATION","25KT"),0) -> 4 | H14: 4 | I14: =IFERROR(GETPIVOTDATA("Sum of Qty PO",'SUM ISOTANK'!$L$1,"Vendor","ENERGI JAYA INOVASI, PT","STATUS","FULL","LOCATION","INBOUND- KOE WTR"), 0) -> 80240 | J14: =GETPIVOTDATA("Count of TANK ID",'SUM ISOTANK'!$L$1,"Vendor","ENERGI JAYA INOVASI, PT","STATUS","FULL","LOCATION","INBOUND - SUB KOE") -> 1 | K14: =IFERROR(GETPIVOTDATA("Sum of Qty PO",'SUM ISOTANK'!$L$1,"Vendor","ENERGI JAYA INOVASI, PT","STATUS","FULL","LOCATION","INBOUND - SUB KOE"),0) -> 22000 | L14: =IFERROR(GETPIVOTDATA("Count of TANK ID",#REF!,"Vendor","ENERGI JAYA INOVASI, PT","STATUS","FULL","LOCATION","INBOUND - HUB SUB"), 0) -> 0 | M14: =IFERROR(GETPIVOTDATA("Sum of Qty PO",'SUM ISOTANK'!$L$1,"Vendor","ENERGI JAYA INOVASI, PT","STATUS","FULL","LOCATION","INBOUND - HUB SUB"), 0) -> 0 | N14: 0 | O14: 0 | P14: =SUM(M14,K14,I14) -> 102240 | Q14: =SUM(M14,K14,I14)-E14 -> -97760 | T14: =SUM(F14,G14,H14,J14,L14,N14,O14) -> 9
B15: ADIMITRA | C15: 150000 | E15: 150000 | F15: =IFERROR(GETPIVOTDATA("Count of TANK ID",'SUM ISOTANK'!$L$1,"Vendor","ADIMITRA PRIMA LESTARI, PT","STATUS","EMPTY","LOCATION","WAREHOUSE"),0) + IFERROR(GETPIVOTDATA("Count of TANK ID",'SUM ISOTANK'!$L$1,"Vendor","ADIMITRA PRIMA LESTARI, PT","STATUS","EMPTY","LOCATION","25KT"),0) -> 0 | G15: =IFERROR(GETPIVOTDATA("Count of TANK ID",'SUM ISOTANK'!$L$1,"Vendor","ADIMITRA PRIMA LESTARI, PT","STATUS","FULL","LOCATION","WAREHOUSE"),0) + IFERROR(GETPIVOTDATA("Count of TANK ID",'SUM ISOTANK'!$L$1,"Vendor","ADIMITRA PRIMA LESTARI, PT","STATUS","FULL","LOCATION","25KT"),0) -> 1 | H15: =GETPIVOTDATA("Count of TANK ID",'SUM ISOTANK'!$L$1,"Vendor","ADIMITRA PRIMA LESTARI, PT","STATUS","FULL","LOCATION","INBOUND- KOE WTR") -> 16 | I15: =IFERROR(GETPIVOTDATA("Sum of Qty PO",'SUM ISOTANK'!$L$1,"Vendor","ADIMITRA PRIMA LESTARI, PT","STATUS","FULL","LOCATION","INBOUND- KOE WTR"), 0) -> 367000 | J15: =GETPIVOTDATA("Count of TANK ID",'SUM ISOTANK'!$L$1,"Vendor","ADIMITRA PRIMA LESTARI, PT","STATUS","FULL","LOCATION","INBOUND - SUB KOE") -> 2 | K15: =IFERROR(GETPIVOTDATA("Sum of Qty PO",'SUM ISOTANK'!$L$1,"Vendor","ADIMITRA PRIMA LESTARI, PT","STATUS","FULL","LOCATION","INBOUND - SUB KOE"),0) -> 44000 | L15: =IFERROR(GETPIVOTDATA("Count of TANK ID",#REF!,"Vendor","ADIMITRA PRIMA LESTARI, PT","STATUS","FULL","LOCATION","INBOUND - HUB SUB"), 0) -> 0 | M15: =IFERROR(GETPIVOTDATA("Sum of Qty PO",'SUM ISOTANK'!$L$1,"Vendor","ADIMITRA PRIMA LESTARI, PT","STATUS","FULL","LOCATION","INBOUND - HUB SUB"), 0) -> 0 | N15: 0 | O15: 0 | P15: =SUM(M15,K15,I15) -> 411000 | Q15: =SUM(M15,K15,I15)-E15 -> 261000 | T15: =SUM(F15,G15,H15,J15,L15,N15,O15) -> 19
B16: TOTAL | C16: =SUM(C12:C15) -> 800000 | E16: =SUM(E12:E15) -> 692000 | F16: =SUM(F12:F15) -> 10 | G16: =SUM(G12:G15) -> 16 | H16: =SUM(H12:H15) -> 39 | I16: =SUM(I12:I15) -> 836660 | J16: =SUM(J12:J15) -> 7 | K16: =SUM(K12:K15) -> 148440 | L16: =SUM(L12:L15) -> 0 | ... T16: =SUM(T12:T15) -> 74
B18: FORECAST ACID JUL '26
B19: Vendor | C19: Forecast ( Kg ) | D19: Price / Kg ( IDR ) | E19: Qty First PO Jul'26 | F19: On Site | H19: Inbound Koe - Wtr | J19: Inbound Sub - Koe | L19: Inbound Hub Sub | N19: Outbound Isotank | P19: Vendor PO Jun'26 | Q19: Difference | R19: Total PO Jun'26 | T19: Total Isotank Rotation
F20: Empty | G20: Full | H20: Qty Isotank | I20: Qty ( Kg ) | J20: Qty Isotank | K20: Qty ( Kg ) | L20: Qty Isotank | M20: Qty ( Kg ) | N20: KOE | O20: HUB | P20: has Supplied ( Kg ) | Q20: Qty ( Kg ) | R20: Qty Isotank | S20: Qty ( Kg )
B21: ROLIMEX | C21: 300000 | D21: 10999 | E21: =SUMIFS('SUM ISOTANK'!G:G, 'SUM ISOTANK'!B:B, "SOC ROLIMEX", 'SUM ISOTANK'!H:H, ">="&DATE(2026,7,1), 'SUM ISOTANK'!H:H, "<="&DATE(2026,7,31)) -> 92000 | F21: 0 | G21: 0 | H21: 0 | I21: 0 | J21: 0 | K21: 0 | N21: 4 | O21: 0 | P21: =SUM(M21,K21,I21) -> 0 | Q21: =SUM(M21,K21,I21)-E21 -> -92000 | R21: =T12-N21-O21 -> 17 | S21: =P12 -> 261490 | T21: =SUM(F21,G21,H21,J21,L21,N21,O21) -> 4
B22: DWIJAYA | C22: 350000 | D22: 12000 | E22: =SUMIFS('SUM ISOTANK'!G:G, 'SUM ISOTANK'!B:B, "SOC DJE", 'SUM ISOTANK'!H:H, ">="&DATE(2026,7,1), 'SUM ISOTANK'!H:H, "<="&DATE(2026,7,31)) -> 115000 | F22: 0 | G22: 0 | H22: 0 | I22: 0 | J22: 0 | K22: 0 | N22: 6 | O22: 0 | P22: =SUM(M22,K22,I22) -> 0 | Q22: =SUM(M22,K22,I22)-E22 -> -115000 | R22: =T13-N22-O22 -> 19 | S22: =P13 -> 210370 | T22: =SUM(F22,G22,H22,J22,L22,N22,O22) -> 6
B23: ENERGI JAYA INOVASI PT | C23: 176000 | D23: 12500 | E23: =SUMIFS('SUM ISOTANK'!G:G, 'SUM ISOTANK'!B:B, "ENERGI JAYA INOVASI, PT", 'SUM ISOTANK'!H:H, ">="&DATE(2026,7,1), 'SUM ISOTANK'!H:H, "<="&DATE(2026,7,31)) -> 0 | F23: 0 | G23: 0 | H23: 0 | I23: 0 | J23: 0 | K23: 0 | P23: =SUM(M23,K23,I23) -> 0 | Q23: =SUM(M23,K23,I23)-E23 -> 0 | R23: =T14-N23-O23 -> 9 | S23: =P14 -> 102240 | T23: =SUM(F23,G23,H23,J23,L23,N23,O23) -> 0
B24: ADIMITRA | C24: 220000 | D24: 15000 | E24: =SUMIFS('SUM ISOTANK'!G:G, 'SUM ISOTANK'!B:B, "ADIMITRA PRIMA LESTARI, PT", 'SUM ISOTANK'!H:H, ">="&DATE(2026,7,1), 'SUM ISOTANK'!H:H, "<="&DATE(2026,7,31)) -> 92000 | F24: 0 | G24: 0 | H24: 0 | I24: 0 | J24: 0 | K24: 0 | P24: =SUM(M24,K24,I24) -> 0 | Q24: =SUM(M24,K24,I24)-E24 -> -92000 | R24: =T15-N24-O24 -> 19 | S24: =P15 -> 411000 | T24: =SUM(F24,G24,H24,J24,L24,N24,O24) -> 0
B25: TOTAL | C25: =SUM(C21:C24) -> 1046000 | E25: =SUM(E21:E24) -> 299000 | F25: =SUM(F21:F24) -> 0 | G25: =SUM(G21:G24) -> 0 | H25: =SUM(H21:H24) -> 0 | I25: =SUM(I21:I24) -> 0 | J25: =SUM(J21:J24) -> 0 | K25: =SUM(K21:K24) -> 0 | L25: =SUM(L21:L24) -> 0 | ... T25: =SUM(T21:T24) -> 10
S27: Total Isotank | T27: =T16+T25 -> 84
G28: =35*21000 -> 735000
G29: 176000
G30: =G29/22000 -> 8

Sheet SUM ISOTANK
B1: Vendor | C1: TANK ID | D1: STATUS | E1: LOCATION | F1: Qty PO | G1: Qty PR | H1: Tanggal Out | I1: PR | L1: Vendor | M1: STATUS | N1: LOCATION | O1: Count of TANK ID | P1: Sum of Qty PO
A2: =TRIM(C2) -> DJEU0303868 | B2: SOC DJE | C2: DJEU0303868 | D2: =_xlfn.XLOOKUP(A2,'ACID & ESCAID STATUS '!D:D,'ACID & ESCAID STATUS '!G:G," ",0,-1) -> EMPTY | E2: =_xlfn.XLOOKUP(A2,'ACID & ESCAID STATUS '!D:D,'ACID & ESCAID STATUS '!H:H," ",0,-1) -> OUTBOUND | F2: =_xlfn.XLOOKUP(A2,'ACID & ESCAID STATUS '!D:D,'ACID & ESCAID STATUS '!E:E," ",0,-1) -> 20860 | G2: =_xlfn.XLOOKUP(A2,'ACID & ESCAID STATUS '!D:D,'ACID & ESCAID STATUS '!P:P," ",0,-1) -> 23000 | H2: =_xlfn.XLOOKUP(A2,'ACID & ESCAID STATUS '!D:D,'ACID & ESCAID STATUS '!R:R, " ",0,-1) -> 46206 | I2: =_xlfn.XLOOKUP(A2,'ACID & ESCAID STATUS '!D:D,'ACID & ESCAID STATUS '!N:N," ",0,-1) -> 99615 | L2: ADIMITRA PRIMA LESTARI, PT | M2: FULL | N2: INBOUND - SUB KOE | O2: 2 | P2: 44000
A3: =TRIM(C3) -> DJEU0303739 | B3: SOC DJE | C3: DJEU0303739 | D3: =_xlfn.XLOOKUP(A3,'ACID & ESCAID STATUS '!D:D,'ACID & ESCAID STATUS '!G:G," ",0,-1) -> EMPTY | E3: =_xlfn.XLOOKUP(A3,'ACID & ESCAID STATUS '!D:D,'ACID & ESCAID STATUS '!H:H," ",0,-1) -> OUTBOUND | F3: =_xlfn.XLOOKUP(A3,'ACID & ESCAID STATUS '!D:D,'ACID & ESCAID STATUS '!E:E," ",0,-1) -> 22700 | G3: =_xlfn.XLOOKUP(A3,'ACID & ESCAID STATUS '!D:D,'ACID & ESCAID STATUS '!P:P," ",0,-1) -> 23000 | H3: =_xlfn.XLOOKUP(A3,'ACID & ESCAID STATUS '!D:D,'ACID & ESCAID STATUS '!R:R, " ",0,-1) -> 46206 | I3: =_xlfn.XLOOKUP(A3,'ACID & ESCAID STATUS '!D:D,'ACID & ESCAID STATUS '!N:N," ",0,-1) -> 99625 | N3: WAREHOUSE | O3: 1 | P3: 25000
A4: =TRIM(C4) -> DJEU0303805 | B4: SOC DJE | C4: DJEU0303805 | D4: =_xlfn.XLOOKUP(A4,'ACID & ESCAID STATUS '!D:D,'ACID & ESCAID STATUS '!G:G," ",0,-1) -> EMPTY | E4: =_xlfn.XLOOKUP(A4,'ACID & ESCAID STATUS '!D:D,'ACID & ESCAID STATUS '!H:H," ",0,-1) -> OUTBOUND | F4: =_xlfn.XLOOKUP(A4,'ACID & ESCAID STATUS '!D:D,'ACID & ESCAID STATUS '!E:E," ",0,-1) -> 20810 | G4: =_xlfn.XLOOKUP(A4,'ACID & ESCAID STATUS '!D:D,'ACID & ESCAID STATUS '!P:P," ",0,-1) -> 23000 | H4: =_xlfn.XLOOKUP(A4,'ACID & ESCAID STATUS '!D:D,'ACID & ESCAID STATUS '!R:R, " ",0,-1) -> 46206 | I4: =_xlfn.XLOOKUP(A4,'ACID & ESCAID STATUS '!D:D,'ACID & ESCAID STATUS '!N:N," ",0,-1) -> 99623 | N4: INBOUND- KOE WTR | O4: 16 | P4: 367000
A5: =TRIM(C5) -> DJEU0303929 | B5: SOC DJE | C5: DJEU0303929 | D5: =_xlfn.XLOOKUP(A5,'ACID & ESCAID STATUS '!D:D,'ACID & ESCAID STATUS '!G:G," ",0,-1) -> FULL | E5: =_xlfn.XLOOKUP(A5,'ACID & ESCAID STATUS '!D:D,'ACID & ESCAID STATUS '!H:H," ",0,-1) -> 25KT | F5: =_xlfn.XLOOKUP(A5,'ACID & ESCAID STATUS '!D:D,'ACID & ESCAID STATUS '!E:E," ",0,-1) -> 19890 | G5: =_xlfn.XLOOKUP(A5,'ACID & ESCAID STATUS '!D:D,'ACID & ESCAID STATUS '!P:P," ",0,-1) -> 23000 | H5: =_xlfn.XLOOKUP(A5,'ACID & ESCAID STATUS '!D:D,'ACID & ESCAID STATUS '!R:R, " ",0,-1) -> 46153 | I5: =_xlfn.XLOOKUP(A5,'ACID & ESCAID STATUS '!D:D,'ACID & ESCAID STATUS '!N:N," ",0,-1) -> 100006 | L5: ENERGI JAYA INOVASI, PT | M5: FULL | N5: INBOUND - SUB KOE | O5: 1 | P5: 22000
A6: =TRIM(C6) -> DJEU0303913 | B6: SOC DJE | C6: DJEU0303913 | D6: =_xlfn.XLOOKUP(A6,'ACID & ESCAID STATUS '!D:D,'ACID & ESCAID STATUS '!G:G," ",0,-1) -> EMPTY | E6: =_xlfn.XLOOKUP(A6,'ACID & ESCAID STATUS '!D:D,'ACID & ESCAID STATUS '!H:H," ",0,-1) -> 25KT | F6: =_xlfn.XLOOKUP(A6,'ACID & ESCAID STATUS '!D:D,'ACID & ESCAID STATUS '!E:E," ",0,-1) -> 20080 | G6: =_xlfn.XLOOKUP(A6,'ACID & ESCAID STATUS '!D:D,'ACID & ESCAID STATUS '!P:P," ",0,-1) -> 23000 | H6: =_xlfn.XLOOKUP(A6,'ACID & ESCAID STATUS '!D:D,'ACID & ESCAID STATUS '!R:R, " ",0,-1) -> 46153 | I6: =_xlfn.XLOOKUP(A6,'ACID & ESCAID STATUS '!D:D,'ACID & ESCAID STATUS '!N:N," ",0,-1) -> 100007 | N6: WAREHOUSE | O6: 4 | P6: 100000
A7: =TRIM(C7) -> DJEU0303908 | B7: SOC DJE | C7: DJEU0303908 | D7: =_xlfn.XLOOKUP(A7,'ACID & ESCAID STATUS '!D:D,'ACID & ESCAID STATUS '!G:G," ",0,-1) -> EMPTY | E7: =_xlfn.XLOOKUP(A7,'ACID & ESCAID STATUS '!D:D,'ACID & ESCAID STATUS '!H:H," ",0,-1) -> OUTBOUND | F7: =_xlfn.XLOOKUP(A7,'ACID & ESCAID STATUS '!D:D,'ACID & ESCAID STATUS '!E:E," ",0,-1) -> 21560 | G7: =_xlfn.XLOOKUP(A7,'ACID & ESCAID STATUS '!D:D,'ACID & ESCAID STATUS '!P:P," ",0,-1) -> 23000 | H7: =_xlfn.XLOOKUP(A7,'ACID & ESCAID STATUS '!D:D,'ACID & ESCAID STATUS '!R:R, " ",0,-1) -> 46206 | I7: =_xlfn.XLOOKUP(A7,'ACID & ESCAID STATUS '!D:D,'ACID & ESCAID STATUS '!N:N," ",0,-1) -> 99624 | N7: INBOUND- KOE WTR | O7: 4 | P7: 80240
A8: =TRIM(C8) -> NTTU1752748 | B8: SOC DJE | C8: NTTU1752748 | D8: =_xlfn.XLOOKUP(A8,'ACID & ESCAID STATUS '!D:D,'ACID & ESCAID STATUS '!G:G," ",0,-1) -> EMPTY | E8: =_xlfn.XLOOKUP(A8,'ACID & ESCAID STATUS '!D:D,'ACID & ESCAID STATUS '!H:H," ",0,-1) -> OUTBOUND | F8: =_xlfn.XLOOKUP(A8,'ACID & ESCAID STATUS '!D:D,'ACID & ESCAID STATUS '!E:E," ",0,-1) -> 21370 | G8: =_xlfn.XLOOKUP(A8,'ACID & ESCAID STATUS '!D:D,'ACID & ESCAID STATUS '!P:P," ",0,-1) -> 23000 | H8: =_xlfn.XLOOKUP(A8,'ACID & ESCAID STATUS '!D:D,'ACID & ESCAID STATUS '!R:R, " ",0,-1) -> 46206 | I8: =_xlfn.XLOOKUP(A8,'ACID & ESCAID STATUS '!D:D,'ACID & ESCAID STATUS '!N:N," ",0,-1) -> 100008 | L8: SOC DJE | M8: EMPTY | N8: 25KT | O8: 1 | P8: 20080
A9: =TRIM(C9) -> DJEU0303699 | B9: SOC DJE | C9: DJEU0303699 | D9: =_xlfn.XLOOKUP(A9,'ACID & ESCAID STATUS '!D:D,'ACID & ESCAID STATUS '!G:G," ",0,-1) -> EMPTY | E9: =_xlfn.XLOOKUP(A9,'ACID & ESCAID STATUS '!D:D,'ACID & ESCAID STATUS '!H:H," ",0,-1) -> WAREHOUSE | F9: =_xlfn.XLOOKUP(A9,'ACID & ESCAID STATUS '!D:D,'ACID & ESCAID STATUS '!E:E," ",0,-1) -> 21250 | G9: =_xlfn.XLOOKUP(A9,'ACID & ESCAID STATUS '!D:D,'ACID & ESCAID STATUS '!P:P," ",0,-1) -> 23000 | H9: =_xlfn.XLOOKUP(A9,'ACID & ESCAID STATUS '!D:D,'ACID & ESCAID STATUS '!R:R, " ",0,-1) -> 46153 | I9: =_xlfn.XLOOKUP(A9,'ACID & ESCAID STATUS '!D:D,'ACID & ESCAID STATUS '!N:N," ",0,-1) -> 100381 | N9: OUTBOUND | O9: 6 | P9: 128580
A10: =TRIM(C10) -> DJEU0303791 | B10: SOC DJE | C10: DJEU0303791 | D10: =_xlfn.XLOOKUP(A10,'ACID & ESCAID STATUS '!D:D,'ACID & ESCAID STATUS '!G:G," ",0,-1) -> EMPTY | E10: =_xlfn.XLOOKUP(A10,'ACID & ESCAID STATUS '!D:D,'ACID & ESCAID STATUS '!H:H," ",0,-1) -> WAREHOUSE | F10: =_xlfn.XLOOKUP(A10,'ACID & ESCAID STATUS '!D:D,'ACID & ESCAID STATUS '!E:E," ",0,-1) -> 21320 | G10: =_xlfn.XLOOKUP(A10,'ACID & ESCAID STATUS '!D:D,'ACID & ESCAID STATUS '!P:P," ",0,-1) -> 23000 | H10: =_xlfn.XLOOKUP(A10,'ACID & ESCAID STATUS '!D:D,'ACID & ESCAID STATUS '!R:R, " ",0,-1) -> 46153 | I10: =_xlfn.XLOOKUP(A10,'ACID & ESCAID STATUS '!D:D,'ACID & ESCAID STATUS '!N:N," ",0,-1) -> 100010 | N10: WAREHOUSE | O10: 5 | P10: 105410
A11: =TRIM(C11) -> DJEU0303765 | B11: SOC DJE | C11: DJEU0303765 | D11: =_xlfn.XLOOKUP(A11,'ACID & ESCAID STATUS '!D:D,'ACID & ESCAID STATUS '!G:G," ",0,-1) -> EMPTY | E11: =_xlfn.XLOOKUP(A11,'ACID & ESCAID STATUS '!D:D,'ACID & ESCAID STATUS '!H:H," ",0,-1) -> WAREHOUSE | F11: =_xlfn.XLOOKUP(A11,'ACID & ESCAID STATUS '!D:D,'ACID & ESCAID STATUS '!E:E," ",0,-1) -> 20960 | G11: =_xlfn.XLOOKUP(A11,'ACID & ESCAID STATUS '!D:D,'ACID & ESCAID STATUS '!P:P," ",0,-1) -> 23000 | H11: =_xlfn.XLOOKUP(A11,'ACID & ESCAID STATUS '!D:D,'ACID & ESCAID STATUS '!R:R, " ",0,-1) -> 46153 | I11: =_xlfn.XLOOKUP(A11,'ACID & ESCAID STATUS '!D:D,'ACID & ESCAID STATUS '!N:N," ",0,-1) -> 100011 | M11: FULL | N11: 25KT | O11: 2 | P11: 41420
A12: =TRIM(C12) -> NTTU1752795 | B12: SOC DJE | C12: NTTU1752795 | D12: =_xlfn.XLOOKUP(A12,'ACID & ESCAID STATUS '!D:D,'ACID & ESCAID STATUS '!G:G," ",0,-1) -> EMPTY | E12: =_xlfn.XLOOKUP(A12,'ACID & ESCAID STATUS '!D:D,'ACID & ESCAID STATUS '!H:H," ",0,-1) -> WAREHOUSE | F12: =_xlfn.XLOOKUP(A12,'ACID & ESCAID STATUS '!D:D,'ACID & ESCAID STATUS '!E:E," ",0,-1) -> 20640 | G12: =_xlfn.XLOOKUP(A12,'ACID & ESCAID STATUS '!D:D,'ACID & ESCAID STATUS '!P:P," ",0,-1) -> 23000 | H12: =_xlfn.XLOOKUP(A12,'ACID & ESCAID STATUS '!D:D,'ACID & ESCAID STATUS '!R:R, " ",0,-1) -> 46175 | I12: =_xlfn.XLOOKUP(A12,'ACID & ESCAID STATUS '!D:D,'ACID & ESCAID STATUS '!N:N," ",0,-1) -> 100382 | N12: INBOUND - SUB KOE | O12: 2 | P12: 41930
A13: =TRIM(C13) -> DJEU0303810 | B13: SOC DJE | C13: DJEU0303810 | D13: =_xlfn.XLOOKUP(A13,'ACID & ESCAID STATUS '!D:D,'ACID & ESCAID STATUS '!G:G," ",0,-1) -> FULL | E13: =_xlfn.XLOOKUP(A13,'ACID & ESCAID STATUS '!D:D,'ACID & ESCAID STATUS '!H:H," ",0,-1) -> WAREHOUSE | F13: =_xlfn.XLOOKUP(A13,'ACID & ESCAID STATUS '!D:D,'ACID & ESCAID STATUS '!E:E," ",0,-1) -> 21300 | G13: =_xlfn.XLOOKUP(A13,'ACID & ESCAID STATUS '!D:D,'ACID & ESCAID STATUS '!P:P," ",0,-1) -> 23000 | H13: =_xlfn.XLOOKUP(A13,'ACID & ESCAID STATUS '!D:D,'ACID & ESCAID STATUS '!R:R, " ",0,-1) -> 46175 | I13: =_xlfn.XLOOKUP(A13,'ACID & ESCAID STATUS '!D:D,'ACID & ESCAID STATUS '!N:N," ",0,-1) -> 100383 | J13: =_xlfn.XLOOKUP(C13,'ACID & ESCAID STATUS '!F:F,'ACID & ESCAID STATUS '!T:T, " ",0,-1) | N13: WAREHOUSE | O13: 6 | P13: 124960
A14: =TRIM(C14) -> NTTU1752711 | B14: SOC DJE | C14: NTTU1752711 | D14: =_xlfn.XLOOKUP(A14,'ACID & ESCAID STATUS '!D:D,'ACID & ESCAID STATUS '!G:G," ",0,-1) -> FULL | E14: =_xlfn.XLOOKUP(A14,'ACID & ESCAID STATUS '!D:D,'ACID & ESCAID STATUS '!H:H," ",0,-1) -> WAREHOUSE | F14: =_xlfn.XLOOKUP(A14,'ACID & ESCAID STATUS '!D:D,'ACID & ESCAID STATUS '!E:E," ",0,-1) -> 20350 | G14: =_xlfn.XLOOKUP(A14,'ACID & ESCAID STATUS '!D:D,'ACID & ESCAID STATUS '!P:P," ",0,-1) -> 0 | H14: =_xlfn.XLOOKUP(A14,'ACID & ESCAID STATUS '!D:D,'ACID & ESCAID STATUS '!R:R, " ",0,-1) -> 0 | I14: =_xlfn.XLOOKUP(A14,'ACID & ESCAID STATUS '!D:D,'ACID & ESCAID STATUS '!N:N," ",0,-1) -> 100384 | N14: INBOUND- KOE WTR | O14: 8 | P14: 168440
A15: =TRIM(C15) -> DJEU0303826 | B15: SOC DJE | C15: DJEU0303826 | D15: =_xlfn.XLOOKUP(A15,'ACID & ESCAID STATUS '!D:D,'ACID & ESCAID STATUS '!G:G," ",0,-1) -> INSTALL | E15: =_xlfn.XLOOKUP(A15,'ACID & ESCAID STATUS '!D:D,'ACID & ESCAID STATUS '!H:H," ",0,-1) -> WAREHOUSE | F15: =_xlfn.XLOOKUP(A15,'ACID & ESCAID STATUS '!D:D,'ACID & ESCAID STATUS '!E:E," ",0,-1) -> 20250 | G15: =_xlfn.XLOOKUP(A15,'ACID & ESCAID STATUS '!D:D,'ACID & ESCAID STATUS '!P:P," ",0,-1) -> 23000 | H15: =_xlfn.XLOOKUP(A15,'ACID & ESCAID STATUS '!D:D,'ACID & ESCAID STATUS '!R:R, " ",0,-1) -> 0 | I15: =_xlfn.XLOOKUP(A15,'ACID & ESCAID STATUS '!D:D,'ACID & ESCAID STATUS '!N:N," ",0,-1) -> 100385 | M15: INSTALL | N15: WAREHOUSE | O15: 1 | P15: 20250
A16: =TRIM(C16) -> DJEU0303852 | B16: SOC DJE | C16: DJEU0303852 | D16: =_xlfn.XLOOKUP(A16,'ACID & ESCAID STATUS '!D:D,'ACID & ESCAID STATUS '!G:G," ",0,-1) -> FULL | E16: =_xlfn.XLOOKUP(A16,'ACID & ESCAID STATUS '!D:D,'ACID & ESCAID STATUS '!H:H," ",0,-1) -> WAREHOUSE | F16: =_xlfn.XLOOKUP(A16,'ACID & ESCAID STATUS '!D:D,'ACID & ESCAID STATUS '!E:E," ",0,-1) -> 21250 | G16: =_xlfn.XLOOKUP(A16,'ACID & ESCAID STATUS '!D:D,'ACID & ESCAID STATUS '!P:P," ",0,-1) -> 23000 | H16: =_xlfn.XLOOKUP(A16,'ACID & ESCAID STATUS '!D:D,'ACID & ESCAID STATUS '!R:R, " ",0,-1) -> 46175 | I16: =_xlfn.XLOOKUP(A16,'ACID & ESCAID STATUS '!D:D,'ACID & ESCAID STATUS '!N:N," ",0,-1) -> 100386 | L16: SOC ROLIMEX | M16: EMPTY | N16: OUTBOUND | O16: 6 | P16: 120940
A17: =TRIM(C17) -> NTTU1752692 | B17: SOC DJE | C17: NTTU1752692 | D17: =_xlfn.XLOOKUP(A17,'ACID & ESCAID STATUS '!D:D,'ACID & ESCAID STATUS '!G:G," ",0,-1) -> FULL | E17: =_xlfn.XLOOKUP(A17,'ACID & ESCAID STATUS '!D:D,'ACID & ESCAID STATUS '!H:H," ",0,-1) -> WAREHOUSE | F17: =_xlfn.XLOOKUP(A17,'ACID & ESCAID STATUS '!D:D,'ACID & ESCAID STATUS '!E:E," ",0,-1) -> 20660 | G17: =_xlfn.XLOOKUP(A17,'ACID & ESCAID STATUS '!D:D,'ACID & ESCAID STATUS '!P:P," ",0,-1) -> 0 | H17: =_xlfn.XLOOKUP(A17,'ACID & ESCAID STATUS '!D:D,'ACID & ESCAID STATUS '!R:R, " ",0,-1) -> 0 | I17: =_xlfn.XLOOKUP(A17,'ACID & ESCAID STATUS '!D:D,'ACID & ESCAID STATUS '!N:N," ",0,-1) -> 100387 | N17: WAREHOUSE | O17: 4 | P17: 82700
A18: =TRIM(C18) -> DJEU0303636 | B18: SOC DJE | C18: DJEU0303636 | D18: =_xlfn.XLOOKUP(A18,'ACID & ESCAID STATUS '!D:D,'ACID & ESCAID STATUS '!G:G," ",0,-1) -> FULL | E18: =_xlfn.XLOOKUP(A18,'ACID & ESCAID STATUS '!D:D,'ACID & ESCAID STATUS '!H:H," ",0,-1) -> WAREHOUSE | F18: =_xlfn.XLOOKUP(A18,'ACID & ESCAID STATUS '!D:D,'ACID & ESCAID STATUS '!E:E," ",0,-1) -> 20030 | G18: =_xlfn.XLOOKUP(A18,'ACID & ESCAID STATUS '!D:D,'ACID & ESCAID STATUS '!P:P," ",0,-1) -> 23000 | H18: =_xlfn.XLOOKUP(A18,'ACID & ESCAID STATUS '!D:D,'ACID & ESCAID STATUS '!R:R, " ",0,-1) -> 46175 | I18: =_xlfn.XLOOKUP(A18,'ACID & ESCAID STATUS '!D:D,'ACID & ESCAID STATUS '!N:N," ",0,-1) -> 100388 | M18: FULL | N18: 25KT | O18: 1 | P18: 20130
A19: =TRIM(C19) -> DJEU0303718 | B19: SOC DJE | C19: DJEU0303718 | D19: =_xlfn.XLOOKUP(A19,'ACID & ESCAID STATUS '!D:D,'ACID & ESCAID STATUS '!G:G," ",0,-1) -> FULL | E19: =_xlfn.XLOOKUP(A19,'ACID & ESCAID STATUS '!D:D,'ACID & ESCAID STATUS '!H:H," ",0,-1) -> 25KT | F19: =_xlfn.XLOOKUP(A19,'ACID & ESCAID STATUS '!D:D,'ACID & ESCAID STATUS '!E:E," ",0,-1) -> 21530 | G19: =_xlfn.XLOOKUP(A19,'ACID & ESCAID STATUS '!D:D,'ACID & ESCAID STATUS '!P:P," ",0,-1) -> 23000 | H19: =_xlfn.XLOOKUP(A19,'ACID & ESCAID STATUS '!D:D,'ACID & ESCAID STATUS '!R:R, " ",0,-1) -> 46175 | I19: =_xlfn.XLOOKUP(A19,'ACID & ESCAID STATUS '!D:D,'ACID & ESCAID STATUS '!N:N," ",0,-1) -> 100389 | N19: INBOUND - SUB KOE | O19: 2 | P19: 40510
A20: =TRIM(C20) -> DJEU0303641 | B20: SOC DJE | C20: DJEU0303641 | D20: =_xlfn.XLOOKUP(A20,'ACID & ESCAID STATUS '!D:D,'ACID & ESCAID STATUS '!G:G," ",0,-1) -> FULL | E20: =_xlfn.XLOOKUP(A20,'ACID & ESCAID STATUS '!D:D,'ACID & ESCAID STATUS '!H:H," ",0,-1) -> WAREHOUSE | F20: =_xlfn.XLOOKUP(A20,'ACID & ESCAID STATUS '!D:D,'ACID & ESCAID STATUS '!E:E," ",0,-1) -> 21370 | G20: =_xlfn.XLOOKUP(A20,'ACID & ESCAID STATUS '!D:D,'ACID & ESCAID STATUS '!P:P," ",0,-1) -> 23000 | H20: =_xlfn.XLOOKUP(A20,'ACID & ESCAID STATUS '!D:D,'ACID & ESCAID STATUS '!R:R, " ",0,-1) -> 46175 | I20: =_xlfn.XLOOKUP(A20,'ACID & ESCAID STATUS '!D:D,'ACID & ESCAID STATUS '!N:N," ",0,-1) -> 100391 | N20: INBOUND- KOE WTR | O20: 11 | P20: 220980
A21: =TRIM(C21) -> DJEU0303702 | B21: SOC DJE | C21: DJEU0303702 | D21: =_xlfn.XLOOKUP(A21,'ACID & ESCAID STATUS '!D:D,'ACID & ESCAID STATUS '!G:G," ",0,-1) -> FULL | E21: =_xlfn.XLOOKUP(A21,'ACID & ESCAID STATUS '!D:D,'ACID & ESCAID STATUS '!H:H," ",0,-1) -> INBOUND - SUB KOE | F21: =_xlfn.XLOOKUP(A21,'ACID & ESCAID STATUS '!D:D,'ACID & ESCAID STATUS '!E:E," ",0,-1) -> 21170 | G21: =_xlfn.XLOOKUP(A21,'ACID & ESCAID STATUS '!D:D,'ACID & ESCAID STATUS '!P:P," ",0,-1) -> 23000 | H21: =_xlfn.XLOOKUP(A21,'ACID & ESCAID STATUS '!D:D,'ACID & ESCAID STATUS '!R:R, " ",0,-1) -> 0 | I21: =_xlfn.XLOOKUP(A21,'ACID & ESCAID STATUS '!D:D,'ACID & ESCAID STATUS '!N:N," ",0,-1) -> 100770 | M21: INSTALL | N21: WAREHOUSE | O21: 1 | P21: 21070
A22: =TRIM(C22) -> NTTU1752780 | B22: SOC DJE | C22: NTTU1752780 | D22: =_xlfn.XLOOKUP(A22,'ACID & ESCAID STATUS '!D:D,'ACID & ESCAID STATUS '!G:G," ",0,-1) -> FULL | E22: =_xlfn.XLOOKUP(A22,'ACID & ESCAID STATUS '!D:D,'ACID & ESCAID STATUS '!H:H," ",0,-1) -> INBOUND - SUB KOE | F22: =_xlfn.XLOOKUP(A22,'ACID & ESCAID STATUS '!D:D,'ACID & ESCAID STATUS '!E:E," ",0,-1) -> 20760 | G22: =_xlfn.XLOOKUP(A22,'ACID & ESCAID STATUS '!D:D,'ACID & ESCAID STATUS '!P:P," ",0,-1) -> 23000 | H22: =_xlfn.XLOOKUP(A22,'ACID & ESCAID STATUS '!D:D,'ACID & ESCAID STATUS '!R:R, " ",0,-1) -> 0 | I22: =_xlfn.XLOOKUP(A22,'ACID & ESCAID STATUS '!D:D,'ACID & ESCAID STATUS '!N:N," ",0,-1) -> 100768 | L22: (blank) | M22: (blank) | N22: (blank)
A23: =TRIM(C23) -> DJEU0303662 | B23: SOC DJE | C23: DJEU0303662 | D23: =_xlfn.XLOOKUP(A23,'ACID & ESCAID STATUS '!D:D,'ACID & ESCAID STATUS '!G:G," ",0,-1) -> FULL | E23: =_xlfn.XLOOKUP(A23,'ACID & ESCAID STATUS '!D:D,'ACID & ESCAID STATUS '!H:H," ",0,-1) -> INBOUND- KOE WTR | F23: =_xlfn.XLOOKUP(A23,'ACID & ESCAID STATUS '!D:D,'ACID & ESCAID STATUS '!E:E," ",0,-1) -> 21180 | G23: =_xlfn.XLOOKUP(A23,'ACID & ESCAID STATUS '!D:D,'ACID & ESCAID STATUS '!P:P," ",0,-1) -> 23000 | H23: =_xlfn.XLOOKUP(A23,'ACID & ESCAID STATUS '!D:D,'ACID & ESCAID STATUS '!R:R, " ",0,-1) -> 0 | I23: =_xlfn.XLOOKUP(A23,'ACID & ESCAID STATUS '!D:D,'ACID & ESCAID STATUS '!N:N," ",0,-1) -> 100577 | L23: Grand Total | O23: 84 | P23: 1795640
A24: =TRIM(C24) -> DJEU0303873 | B24: SOC DJE | C24: DJEU0303873 | D24: =_xlfn.XLOOKUP(A24,'ACID & ESCAID STATUS '!D:D,'ACID & ESCAID STATUS '!G:G," ",0,-1) -> FULL | E24: =_xlfn.XLOOKUP(A24,'ACID & ESCAID STATUS '!D:D,'ACID & ESCAID STATUS '!H:H," ",0,-1) -> INBOUND- KOE WTR | F24: =_xlfn.XLOOKUP(A24,'ACID & ESCAID STATUS '!D:D,'ACID & ESCAID STATUS '!E:E," ",0,-1) -> 21390 | G24: =_xlfn.XLOOKUP(A24,'ACID & ESCAID STATUS '!D:D,'ACID & ESCAID STATUS '!P:P," ",0,-1) -> 23000 | H24: =_xlfn.XLOOKUP(A24,'ACID & ESCAID STATUS '!D:D,'ACID & ESCAID STATUS '!R:R, " ",0,-1) -> 0 | I24: =_xlfn.XLOOKUP(A24,'ACID & ESCAID STATUS '!D:D,'ACID & ESCAID STATUS '!N:N," ",0,-1) -> 100572
A25: =TRIM(C25) -> NTTU1752727 | B25: SOC DJE | C25: NTTU1752727 | D25: =_xlfn.XLOOKUP(A25,'ACID & ESCAID STATUS '!D:D,'ACID & ESCAID STATUS '!G:G," ",0,-1) -> FULL | E25: =_xlfn.XLOOKUP(A25,'ACID & ESCAID STATUS '!D:D,'ACID & ESCAID STATUS '!H:H," ",0,-1) -> INBOUND- KOE WTR | F25: =_xlfn.XLOOKUP(A25,'ACID & ESCAID STATUS '!D:D,'ACID & ESCAID STATUS '!E:E," ",0,-1) -> 20830 | G25: =_xlfn.XLOOKUP(A25,'ACID & ESCAID STATUS '!D:D,'ACID & ESCAID STATUS '!P:P," ",0,-1) -> 23000 | H25: =_xlfn.XLOOKUP(A25,'ACID & ESCAID STATUS '!D:D,'ACID & ESCAID STATUS '!R:R, " ",0,-1) -> 0 | I25: =_xlfn.XLOOKUP(A25,'ACID & ESCAID STATUS '!D:D,'ACID & ESCAID STATUS '!N:N," ",0,-1) -> 100769
A26: =TRIM(C26) -> NTTU1752732 | B26: SOC DJE | C26: NTTU1752732 | D26: =_xlfn.XLOOKUP(A26,'ACID & ESCAID STATUS '!D:D,'ACID & ESCAID STATUS '!G:G," ",0,-1) -> FULL | E26: =_xlfn.XLOOKUP(A26,'ACID & ESCAID STATUS '!D:D,'ACID & ESCAID STATUS '!H:H," ",0,-1) -> INBOUND- KOE WTR | F26: =_xlfn.XLOOKUP(A26,'ACID & ESCAID STATUS '!D:D,'ACID & ESCAID STATUS '!E:E," ",0,-1) -> 20720 | G26: =_xlfn.XLOOKUP(A26,'ACID & ESCAID STATUS '!D:D,'ACID & ESCAID STATUS '!P:P," ",0,-1) -> 23000 | H26: =_xlfn.XLOOKUP(A26,'ACID & ESCAID STATUS '!D:D,'ACID & ESCAID STATUS '!R:R, " ",0,-1) -> 0 | I26: =_xlfn.XLOOKUP(A26,'ACID & ESCAID STATUS '!D:D,'ACID & ESCAID STATUS '!N:N," ",0,-1) -> 100576
A27: =TRIM(C27) -> DJEU0303894 | B27: SOC DJE | C27: DJEU0303894 | D27: =_xlfn.XLOOKUP(A27,'ACID & ESCAID STATUS '!D:D,'ACID & ESCAID STATUS '!G:G," ",0,-1) -> EMPTY | E27: =_xlfn.XLOOKUP(A27,'ACID & ESCAID STATUS '!D:D,'ACID & ESCAID STATUS '!H:H," ",0,-1) -> OUTBOUND | F27: =_xlfn.XLOOKUP(A27,'ACID & ESCAID STATUS '!D:D,'ACID & ESCAID STATUS '!E:E," ",0,-1) -> 21280 | G27: =_xlfn.XLOOKUP(A27,'ACID & ESCAID STATUS '!D:D,'ACID & ESCAID STATUS '!P:P," ",0,-1) -> 23000 | H27: =_xlfn.XLOOKUP(A27,'ACID & ESCAID STATUS '!D:D,'ACID & ESCAID STATUS '!R:R, " ",0,-1) -> 46194 | I27: =_xlfn.XLOOKUP(A27,'ACID & ESCAID STATUS '!D:D,'ACID & ESCAID STATUS '!N:N," ",0,-1) -> 99437
A28: =TRIM(C28) -> NTTU1752687 | B28: SOC DJE | C28: NTTU1752687 | D28: =_xlfn.XLOOKUP(A28,'ACID & ESCAID STATUS '!D:D,'ACID & ESCAID STATUS '!G:G," ",0,-1) -> FULL | E28: =_xlfn.XLOOKUP(A28,'ACID & ESCAID STATUS '!D:D,'ACID & ESCAID STATUS '!H:H," ",0,-1) -> INBOUND- KOE WTR | F28: =_xlfn.XLOOKUP(A28,'ACID & ESCAID STATUS '!D:D,'ACID & ESCAID STATUS '!E:E," ",0,-1) -> 20850 | G28: =_xlfn.XLOOKUP(A28,'ACID & ESCAID STATUS '!D:D,'ACID & ESCAID STATUS '!P:P," ",0,-1) -> 23000 | H28: =_xlfn.XLOOKUP(A28,'ACID & ESCAID STATUS '!D:D,'ACID & ESCAID STATUS '!R:R, " ",0,-1) -> 0 | I28: =_xlfn.XLOOKUP(A28,'ACID & ESCAID STATUS '!D:D,'ACID & ESCAID STATUS '!N:N," ",0,-1) -> 100766
A29: =TRIM(C29) -> DJEU0303750 | B29: SOC DJE | C29: DJEU0303750 | D29: =_xlfn.XLOOKUP(A29,'ACID & ESCAID STATUS '!D:D,'ACID & ESCAID STATUS '!G:G," ",0,-1) -> FULL | E29: =_xlfn.XLOOKUP(A29,'ACID & ESCAID STATUS '!D:D,'ACID & ESCAID STATUS '!H:H," ",0,-1) -> INBOUND- KOE WTR | F29: =_xlfn.XLOOKUP(A29,'ACID & ESCAID STATUS '!D:D,'ACID & ESCAID STATUS '!E:E," ",0,-1) -> 21480 | G29: =_xlfn.XLOOKUP(A29,'ACID & ESCAID STATUS '!D:D,'ACID & ESCAID STATUS '!P:P," ",0,-1) -> 23000 | H29: =_xlfn.XLOOKUP(A29,'ACID & ESCAID STATUS '!D:D,'ACID & ESCAID STATUS '!R:R, " ",0,-1) -> 0 | I29: =_xlfn.XLOOKUP(A29,'ACID & ESCAID STATUS '!D:D,'ACID & ESCAID STATUS '!N:N," ",0,-1) -> 100573
A30: =TRIM(C30) -> NTTU1752753 | B30: SOC DJE | C30: NTTU1752753 | D30: =_xlfn.XLOOKUP(A30,'ACID & ESCAID STATUS '!D:D,'ACID & ESCAID STATUS '!G:G," ",0,-1) -> FULL | E30: =_xlfn.XLOOKUP(A30,'ACID & ESCAID STATUS '!D:D,'ACID & ESCAID STATUS '!H:H," ",0,-1) -> INBOUND- KOE WTR | F30: =_xlfn.XLOOKUP(A30,'ACID & ESCAID STATUS '!D:D,'ACID & ESCAID STATUS '!E:E," ",0,-1) -> 20560 | G30: =_xlfn.XLOOKUP(A30,'ACID & ESCAID STATUS '!D:D,'ACID & ESCAID STATUS '!P:P," ",0,-1) -> 23000 | H30: =_xlfn.XLOOKUP(A30,'ACID & ESCAID STATUS '!D:D,'ACID & ESCAID STATUS '!R:R, " ",0,-1) -> 0 | I30: =_xlfn.XLOOKUP(A30,'ACID & ESCAID STATUS '!D:D,'ACID & ESCAID STATUS '!N:N," ",0,-1) -> 100574
A31: =TRIM(C31) -> DJEU0303615 | B31: SOC DJE | C31: DJEU0303615 | D31: =_xlfn.XLOOKUP(A31,'ACID & ESCAID STATUS '!D:D,'ACID & ESCAID STATUS '!G:G," ",0,-1) -> FULL | E31: =_xlfn.XLOOKUP(A31,'ACID & ESCAID STATUS '!D:D,'ACID & ESCAID STATUS '!H:H," ",0,-1) -> INBOUND- KOE WTR | F31: =_xlfn.XLOOKUP(A31,'ACID & ESCAID STATUS '!D:D,'ACID & ESCAID STATUS '!E:E," ",0,-1) -> 21430 | G31: =_xlfn.XLOOKUP(A31,'ACID & ESCAID STATUS '!D:D,'ACID & ESCAID STATUS '!P:P," ",0,-1) -> 23000 | H31: =_xlfn.XLOOKUP(A31,'ACID & ESCAID STATUS '!D:D,'ACID & ESCAID STATUS '!R:R, " ",0,-1) -> 0 | I31: =_xlfn.XLOOKUP(A31,'ACID & ESCAID STATUS '!D:D,'ACID & ESCAID STATUS '!N:N," ",0,-1) -> 100575
A32: =TRIM(C32) -> DJEU0303770 | B32: SOC DJE | C32: DJEU0303770 | D32: =_xlfn.XLOOKUP(A32,'ACID & ESCAID STATUS '!D:D,'ACID & ESCAID STATUS '!G:G," ",0,-1) -> EMPTY | E32: =_xlfn.XLOOKUP(A32,'ACID & ESCAID STATUS '!D:D,'ACID & ESCAID STATUS '!H:H," ",0,-1) -> WAREHOUSE | F32: =_xlfn.XLOOKUP(A32,'ACID & ESCAID STATUS '!D:D,'ACID & ESCAID STATUS '!E:E," ",0,-1) -> 21240 | G32: =_xlfn.XLOOKUP(A32,'ACID & ESCAID STATUS '!D:D,'ACID & ESCAID STATUS '!P:P," ",0,-1) -> 23000 | H32: =_xlfn.XLOOKUP(A32,'ACID & ESCAID STATUS '!D:D,'ACID & ESCAID STATUS '!R:R, " ",0,-1) -> 46175 | I32: =_xlfn.XLOOKUP(A32,'ACID & ESCAID STATUS '!D:D,'ACID & ESCAID STATUS '!N:N," ",0,-1) -> 100390
A33: =TRIM(C33) -> SJIU2221578 | B33: SOC ROLIMEX | C33: SJIU2221578 | D33: =_xlfn.XLOOKUP(A33,'ACID & ESCAID STATUS '!D:D,'ACID & ESCAID STATUS '!G:G," ",0,-1) -> EMPTY | E33: =_xlfn.XLOOKUP(A33,'ACID & ESCAID STATUS '!D:D,'ACID & ESCAID STATUS '!H:H," ",0,-1) -> WAREHOUSE | F33: =_xlfn.XLOOKUP(A33,'ACID & ESCAID STATUS '!D:D,'ACID & ESCAID STATUS '!E:E," ",0,-1) -> 20870 | G33: =_xlfn.XLOOKUP(A33,'ACID & ESCAID STATUS '!D:D,'ACID & ESCAID STATUS '!P:P," ",0,-1) -> 23000 | H33: =_xlfn.XLOOKUP(A33,'ACID & ESCAID STATUS '!D:D,'ACID & ESCAID STATUS '!R:R, " ",0,-1) -> 46153 | I33: =_xlfn.XLOOKUP(A33,'ACID & ESCAID STATUS '!D:D,'ACID & ESCAID STATUS '!N:N," ",0,-1) -> 99997
A34: =TRIM(C34) -> SJIU2221710 | B34: SOC ROLIMEX | C34: SJIU2221710 | D34: =_xlfn.XLOOKUP(A34,'ACID & ESCAID STATUS '!D:D,'ACID & ESCAID STATUS '!G:G," ",0,-1) -> FULL | E34: =_xlfn.XLOOKUP(A34,'ACID & ESCAID STATUS '!D:D,'ACID & ESCAID STATUS '!H:H," ",0,-1) -> INBOUND - SUB KOE | F34: =_xlfn.XLOOKUP(A34,'ACID & ESCAID STATUS '!D:D,'ACID & ESCAID STATUS '!E:E," ",0,-1) -> 20270 | G34: =_xlfn.XLOOKUP(A34,'ACID & ESCAID STATUS '!D:D,'ACID & ESCAID STATUS '!P:P," ",0,-1) -> 23000 | H34: =_xlfn.XLOOKUP(A34,'ACID & ESCAID STATUS '!D:D,'ACID & ESCAID STATUS '!R:R, " ",0,-1) -> 0 | I34: =_xlfn.XLOOKUP(A34,'ACID & ESCAID STATUS '!D:D,'ACID & ESCAID STATUS '!N:N," ",0,-1) -> 100761
A35: =TRIM(C35) -> SJIU2221541 | B35: SOC ROLIMEX | C35: SJIU2221541 | D35: =_xlfn.XLOOKUP(A35,'ACID & ESCAID STATUS '!D:D,'ACID & ESCAID STATUS '!G:G," ",0,-1) -> FULL | E35: =_xlfn.XLOOKUP(A35,'ACID & ESCAID STATUS '!D:D,'ACID & ESCAID STATUS '!H:H," ",0,-1) -> INBOUND- KOE WTR | F35: =_xlfn.XLOOKUP(A35,'ACID & ESCAID STATUS '!D:D,'ACID & ESCAID STATUS '!E:E," ",0,-1) -> 20030 | G35: =_xlfn.XLOOKUP(A35,'ACID & ESCAID STATUS '!D:D,'ACID & ESCAID STATUS '!P:P," ",0,-1) -> 23000 | H35: =_xlfn.XLOOKUP(A35,'ACID & ESCAID STATUS '!D:D,'ACID & ESCAID STATUS '!R:R, " ",0,-1) -> 0 | I35: =_xlfn.XLOOKUP(A35,'ACID & ESCAID STATUS '!D:D,'ACID & ESCAID STATUS '!N:N," ",0,-1) -> 100584
... A88: =TRIM(C88) -> NTTU1754442 | B88: ADIMITRA PRIMA LESTARI, PT | C88: NTTU1754442 | D88: =_xlfn.XLOOKUP(A88,'ACID & ESCAID STATUS '!D:D,'ACID & ESCAID STATUS '!G:G," ",0,-1) -> 0 | E88: =_xlfn.XLOOKUP(A88,'ACID & ESCAID STATUS '!D:D,'ACID & ESCAID STATUS '!H:H," ",0,-1) -> VENDOR | F88: =_xlfn.XLOOKUP(A88,'ACID & ESCAID STATUS '!D:D,'ACID & ESCAID STATUS '!E:E," ",0,-1) -> 0 | G88: =_xlfn.XLOOKUP(A88,'ACID & ESCAID STATUS '!D:D,'ACID & ESCAID STATUS '!P:P," ",0,-1) -> 23000 | H88: =_xlfn.XLOOKUP(A88,'ACID & ESCAID STATUS '!D:D,'ACID & ESCAID STATUS '!R:R, " ",0,-1) -> 46212 | I88: =_xlfn.XLOOKUP(A88,'ACID & ESCAID STATUS '!D:D,'ACID & ESCAID STATUS '!N:N," ",0,-1) -> 0
A89: =TRIM(C89) | I89: =_xlfn.XLOOKUP(A89,'ACID & ESCAID STATUS '!D:D,'ACID & ESCAID STATUS '!N:N," ",0,-1)
A90: =TRIM(C90) | I90: =_xlfn.XLOOKUP(A90,'ACID & ESCAID STATUS '!D:D,'ACID & ESCAID STATUS '!N:N," ",0,-1)
A91: =TRIM(C91) | I91: =_xlfn.XLOOKUP(A91,'ACID & ESCAID STATUS '!D:D,'ACID & ESCAID STATUS '!N:N," ",0,-1)
A92: =TRIM(C92) | I92: =_xlfn.XLOOKUP(A92,'ACID & ESCAID STATUS '!D:D,'ACID & ESCAID STATUS '!N:N," ",0,-1)
...

Sheet ACID & ESCAID STATUS 
D1: STOCK TAKE PERIODE JUNE 2026
E2: =TODAY() -> 46215 | J2: 100386
E3: 6823-03-114225 | F3: DWI005IDR | G3: ROL001IDR
C4: Vendor | D4: TANK ID | E4: QTY | F4: UoM | G4: STATUS | H4: LOCATION | I4: QTY ISSUED | J4: Date Empty | K4: PS | L4: CM IN | M4: DATE IN | N4: PO IN | O4: PR/PO OUT | P4: QTY PR | Q4: CM OUT | R4: DATE OUT
A5: =N5 -> 96649 | C5: ADI106IDR | D5: SJIU2522988 | E5: 25000 | F5: KG | G5: EMPTY | H5: OUTBOUND | I5: 25000 | J5: 46017 | K5: 214663 | L5: V271 29 OKT 2025 | M5: 45959 | N5: 96649 | O5: Di GOOD RETURN | Q5: LCT PERMATA 17 Voy 1214 ETD 25122025 | R5: 46016
A6: =N6 -> 96650 | B6: =TRIM(D6) -> SJIU2522993 | C6: ADI106IDR | D6: SJIU2522993 | E6: 25000 | F6: KG | G6: EMPTY | H6: OUTBOUND | I6: 25000 | J6: 46017 | K6: 214663 | L6: V271 29 OKT 2025 | M6: 45959 | N6: 96650 | O6: Di GOOD RETURN | P6: 23000 | Q6: LCT PERMATA 17 Voy 1215 ETD 03012026 | R6: 46025 | S6: REFILL NEW ISOTANK : | T6: =+S6&D6 -> REFILL NEW ISOTANK :SJIU2522993
A7: =N7 -> 96648 | B7: =TRIM(D7) -> SJIU2522972 | C7: ADI106IDR | D7: SJIU2522972 | E7: 25000 | F7: KG | G7: EMPTY | H7: OUTBOUND | I7: 25000 | L7: V271 29 OKT 2025 | M7: 45959 | N7: 96648 | O7: Di GOOD RETURN | P7: 23000 | Q7: LCT PERMATA 17 Voy 1215 ETD 03012026 | R7: 46025 | S7: REFILL NEW ISOTANK : | T7: =+S7&D7 -> REFILL NEW ISOTANK :SJIU2522972
A8: =N8 -> 96647 | B8: =TRIM(D8) -> SJIU2522967 | C8: ADI106IDR | D8: SJIU2522967 | E8: 25000 | F8: KG | G8: EMPTY | H8: OUTBOUND | I8: 25000 | J8: 46022 | K8: 214867 | L8: V271 29 OKT 2025 | M8: 45959 | N8: 96647 | O8: Di GOOD RETURN | P8: 23000 | Q8: LCT PERMATA 17 Voy 1215 ETD 03012026 | R8: 46025 | S8: REFILL NEW ISOTANK : | T8: =+S8&D8 -> REFILL NEW ISOTANK :SJIU2522967
A9: =N9 -> 96075 | B9: =TRIM(D9) -> NTTU1753765 | C9: ROL100IDR | D9: NTTU1753765 | E9: 20590 | F9: KG | G9: EMPTY | H9: OUTBOUND | I9: 20590 | J9: 46023 | K9: 214867 | L9: V273 21 NOV 2025 | M9: 45982 | N9: 96075 | P9: 23000 | Q9: LCT PERMATA 17 Voy 1215 ETD 03012026 | R9: 46025 | S9: REFILL NEW ISOTANK : | T9: =+S9&D9 -> REFILL NEW ISOTANK :NTTU1753765
A10: =N10 -> 96651 | B10: =TRIM(D10) -> SJIU2422612 | C10: ADI106IDR | D10: SJIU2422612 | E10: 25000 | F10: KG | G10: EMPTY | H10: OUTBOUND | I10: 25000 | J10: 46025 | K10: 214908 | L10: V276 23 Dec 2025 | M10: 46014 | N10: 96651 | O10: Di GOOD RETURN | P10: 23000 | Q10: LCT PERMATA 17 Voy 1216 ETD 03012026 | R10: 46025 | S10: REFILL NEW ISOTANK : | T10: =+S10&D10 -> REFILL NEW ISOTANK :SJIU2422612
A11: =N11 -> 96652 | B11: =TRIM(D11) -> SJIU2422628 | C11: ADI106IDR | D11: SJIU2422628 | E11: 25000 | F11: KG | G11: EMPTY | H11: OUTBOUND | I11: 25000 | J11: 46034 | K11: 215181 | L11: V276 23 Dec 2025 | M11: 46014 | N11: 96652 | O11: Di GOOD RETURN | P11: 23000 | Q11: LCT PERMATA 17 Voy 1216 ETD 23012026 | R11: 46025 | S11: REFILL NEW ISOTANK : | T11: =+S11&D11 -> REFILL NEW ISOTANK :SJIU2422628
A12: =N12 -> 97114 | B12: =TRIM(D12) -> DJEU0303636 | C12: DWI101IDR | D12: DJEU0303636 | E12: 20370 | F12: KG | G12: EMPTY | H12: OUTBOUND | I12: 20370 | J12: 46034 | K12: 215181 | L12: V275 14 Dec 2025 | M12: 46005 | N12: 97114 | P12: 23000 | Q12: LCT PERMATA 17 Voy 1216 ETD 23012026 | R12: 46025 | S12: REFILL NEW ISOTANK : | T12: =+S12&D12 -> REFILL NEW ISOTANK :DJEU0303636
A13: =N13 -> 96092 | B13: =TRIM(D13) -> NTTU1753739 | C13: ROL100IDR | D13: NTTU1753739 | E13: 20760 | F13: KG | G13: EMPTY | H13: OUTBOUND | I13: 20760 | J13: 46034 | K13: 215181 | L13: V273 21 NOV 2025 | M13: 45982 | N13: 96092 | P13: 23000 | Q13: LCT PERMATA 17 Voy 1216 ETD 23012026 | R13: 46025 | S13: REFILL NEW ISOTANK : | T13: =+S13&D13 -> REFILL NEW ISOTANK :NTTU1753739
A14: =N14 -> 95545 | B14: =TRIM(D14) -> NTTU1753702 | C14: ROL100IDR | D14: NTTU1753702 | E14: 19790 | F14: KG | G14: EMPTY | H14: OUTBOUND | I14: 19790 | J14: 46037 | L14: V271 29 OKT 2025 | M14: 45959 | N14: 95545 | P14: 23000 | Q14: LCT PERMATA 17 Voy 1216 ETD 23012026 | R14: 46025 | S14: REFILL NEW ISOTANK : | T14: =+S14&D14 -> REFILL NEW ISOTANK :NTTU1753702
A15: =N15 -> 97116 | B15: =TRIM(D15) -> NTTU1752748 | C15: DWI101IDR | D15: NTTU1752748 | E15: 20330 | F15: KG | G15: EMPTY | H15: OUTBOUND | I15: 20330 | J15: 46038 | K15: 215498 | L15: V275 14 Dec 2025 | M15: 46005 | N15: 97116 | P15: 23000 | Q15: LCT PERMATA 17 Voy 1216 ETD 23012026 | R15: 46025 | S15: REFILL NEW ISOTANK : | T15: =+S15&D15 -> REFILL NEW ISOTANK :NTTU1752748
A16: =N16 -> 97245 | B16: =TRIM(D16) -> DJEU0303810 | C16: DWI101IDR | D16: DJEU0303810 | E16: 20340 | F16: KG | G16: EMPTY | H16: OUTBOUND | I16: 20340 | J16: 46039 | K16: 215323 | L16: V275 14 Dec 2025 | M16: 46005 | N16: 97245 | O16: 98457 | P16: 23000 | Q16: LCT PERMATA 17 Voy 1216 ETD 23012026 | R16: 46025 | S16: REFILL NEW ISOTANK : | T16: =+S16&D16 -> REFILL NEW ISOTANK :DJEU0303810
A17: =N17 -> 97113 | B17: =TRIM(D17) -> DJEU0303699 | C17: DWI101IDR | D17: DJEU0303699 | E17: 20180 | F17: KG | G17: EMPTY | H17: OUTBOUND | I17: 20180 | K17: 215323 | L17: V275 14 Dec 2025 | M17: 46005 | N17: 97113 | O17: 98326 | P17: 23000 | Q17: LCT PERMATA 17 Voy 1216 ETD 23012026 | R17: 46025 | S17: REFILL NEW ISOTANK : | T17: =+S17&D17 -> REFILL NEW ISOTANK :DJEU0303699
A18: =N18 -> 97246 | B18: =TRIM(D18) -> DJEU0303826 | C18: DWI101IDR | D18: DJEU0303826 | E18: 20420 | F18: KG | G18: EMPTY | H18: OUTBOUND | I18: 20420 | J18: 46042 | K18: 215498 | L18: V275 14 Dec 2025 | M18: 46005 | N18: 97246 | O18: 98986 | P18: 23000 | Q18: LCT PERMATA 17 Voy 1216 ETD 23012026 | R18: 46045 | S18: REFILL NEW ISOTANK : | T18: =+S18&D18 -> REFILL NEW ISOTANK :DJEU0303826
A19: =N19 -> 97247 | B19: =TRIM(D19) -> DJEU0303718 | C19: DWI101IDR | D19: DJEU0303718 | E19: 20400 | F19: KG | G19: EMPTY | H19: OUTBOUND | I19: 20400 | J19: 46040 | K19: 215323 | L19: V275 14 Dec 2025 | M19: 46005 | N19: 97247 | O19: 98985 | P19: 23000 | Q19: LCT PERMATA 17 Voy 1216 ETD 23012026 | R19: 46045 | S19: REFILL NEW ISOTANK : | T19: =+S19&D19 -> REFILL NEW ISOTANK :DJEU0303718
A20: =N20 -> 97115 | B20: =TRIM(D20) -> DJEU0303791 | C20: DWI101IDR | D20: DJEU0303791 | E20: 20390 | F20: KG | G20: EMPTY | H20: OUTBOUND | I20: 20390 | J20: 46044 | K20: 215498 | L20: V275 14 Dec 2025 | M20: 46005 | N20: 97115 | P20: 23000 | Q20: LCT PERMATA 17 Voy 1216 ETD 23012026 | R20: 46045 | S20: REFILL NEW ISOTANK : | T20: =+S20&D20 -> REFILL NEW ISOTANK :DJEU0303791
A21: =N21 -> 97383 | B21: =TRIM(D21) -> NTTU1752711 | C21: DWI101IDR | D21: NTTU1752711 | E21: 21340 | F21: KG | G21: EMPTY | H21: OUTBOUND | I21: 21340 | J21: 46052 | K21: 215665 | L21: V276 23 Dec 2025 | M21: 46014 | N21: 97383 | O21: 98458 | P21: 23000 | Q21: LCT PERMATA 17 VOY 1217 ETD 03022026 | R21: 46056 | S21: REFILL NEW ISOTANK : | T21: =+S21&D21 -> REFILL NEW ISOTANK :NTTU1752711
A22: =N22 -> 97379 | B22: =TRIM(D22) -> DJEU0303765 | C22: DWI101IDR | D22: DJEU0303765 | E22: 21390 | F22: KG | G22: EMPTY | H22: OUTBOUND | I22: 21390 | J22: 46049 | K22: 215543 | L22: V276 23 Dec 2025 | M22: 46014 | N22: 97379 | O22: 98455 | P22: 23000 | Q22: LCT PERMATA 17 VOY 1217 ETD 03022026 | R22: 46056 | S22: REFILL NEW ISOTANK : | T22: =+S22&D22 -> REFILL NEW ISOTANK :DJEU0303765
A23: =N23 -> 97381 | B23: =TRIM(D23) -> NTTU1752795 | C23: DWI101IDR | D23: NTTU1752795 | E23: 21370 | F23: KG | G23: EMPTY | H23: OUTBOUND | I23: 21370 | J23: 46050 | K23: 215543 | L23: V276 23 Dec 2025 | M23: 46014 | N23: 97381 | O23: 98456 GR qty 21070 | P23: 23000 | Q23: LCT PERMATA 17 VOY 1217 ETD 03022026 | R23: 46056 | S23: REFILL NEW ISOTANK : | T23: =+S23&D23 -> REFILL NEW ISOTANK :NTTU1752795
A24: =N24 -> 97382 | B24: =TRIM(D24) -> DJEU0303750 | C24: DWI101IDR | D24: DJEU0303750 | E24: 21380 | F24: KG | G24: EMPTY | H24: OUTBOUND | I24: 21380 | J24: 46046 | K24: 215498 | L24: V276 23 Dec 2025 | M24: 46014 | N24: 97382 | O24: 98457 | P24: 23000 | Q24: LCT PERMATA 17 VOY 1217 ETD 03022026 | R24: 46056 | S24: REFILL NEW ISOTANK : | T24: =+S24&D24 -> REFILL NEW ISOTANK :DJEU0303750
A25: =N25 -> 97712 | B25: =D25 -> NTTU1752671 | C25: DWI101IDR | D25: NTTU1752671 | E25: 21400 | F25: KG | G25: EMPTY | H25: OUTBOUND | I25: 21400 | J25: 46060 | K25: 215860 | L25: V277 02 JAN 2026 | M25: 46024 | N25: 97712 | O25: 98987 | P25: 23000 | Q25: LCT PERMATA 17 : 1218 ETD 22-02-2026 | R25: 46075 | S25: REFILL NEW ISOTANK : | T25: =+S25&D25 -> REFILL NEW ISOTANK :NTTU1752671
A26: =N26 -> 97713 | B26: =D26 -> NTTU1752692 | C26: DWI101IDR | D26: NTTU1752692 | E26: 21420 | F26: KG | G26: EMPTY | H26: OUTBOUND | I26: 21420 | J26: 46060 | K26: 215877 | L26: V277 02 JAN 2026 | M26: 46024 | N26: 97713 | O26: 98988 | P26: 23000 | Q26: LCT PERMATA 17 : 1218 ETD 22-02-2026 | R26: 46075 | S26: REFILL NEW ISOTANK : | T26: =+S26&D26 -> REFILL NEW ISOTANK :NTTU1752692
A27: =TRIM(N27) -> 96653 | B27: =D27 -> SJIU2422633 | C27: ADI106IDR | D27: SJIU2422633 | E27: 28200 | F27: KG | G27: EMPTY | H27: OUTBOUND | I27: 27000 | J27: 45716 | K27: 216425 | L27: V278 17 JAN 2026 | M27: 46039 | N27: 96653 | O27: Additional Tank - tidak perlu di naikkan PR | P27: 23000 | Q27: LCT PERMATA 17 : 1218 ETD 22-02-2026 | R27: 46075 | S27: REFILL NEW ISOTANK : | T27: =+S27&D27 -> REFILL NEW ISOTANK :SJIU2422633
A28: =TRIM(N28) -> 96654 | B28: =D28 -> SJIU2422649 | C28: ADI106IDR | D28: SJIU2422649 | E28: 28200 | F28: KG | G28: EMPTY | H28: OUTBOUND | I28: 27000 | J28: 45716 | K28: 216425 | L28: V278 17 JAN 2026 | M28: 46039 | N28: 96654 | O28: Additional Tank - tidak perlu di naikkan PR | P28: 23000 | Q28: LCT PERMATA 17 : 1218 ETD 22-02-2026 | R28: 46075 | S28: REFILL NEW ISOTANK : | T28: =+S28&D28 -> REFILL NEW ISOTANK :SJIU2422649
A29: =TRIM(N29) -> 96657 | B29: =D29 -> SJIU2422660 | C29: ADI106IDR | D29: SJIU2422660 | E29: 28200 | F29: KG | G29: EMPTY | H29: OUTBOUND | I29: 27000 | J29: 45716 | K29: 216425 | L29: V278 17 JAN 2026 | M29: 46039 | N29: 96657 | O29: Additional Tank - tidak perlu di naikkan PR | P29: 23000 | Q29: LCT PERMATA 17 : 1218 ETD 22-02-2026 | R29: 46075 | S29: REFILL NEW ISOTANK : | T29: =+S29&D29 -> REFILL NEW ISOTANK :SJIU2422660
A30: =TRIM(N30) -> 97715 | B30: =D30 -> NTTU1752732 | C30: DWI101IDR | D30: NTTU1752732 | E30: 21260 | F30: KG | G30: EMPTY | H30: OUTBOUND | I30: 21260 | J30: 46066 | K30: 216014 | L30: V277 02 JAN 2026 | M30: 46024 | N30: 97715 | O30: Additional Tank - tidak perlu di naikkan PR | P30: 23000 | Q30: LCT P17 VOY 1220 ETD 18032026 | R30: 46099 | S30: REFILL NEW ISOTANK : | T30: =+S30&D30 -> REFILL NEW ISOTANK :NTTU1752732
A31: =TRIM(N31) -> 97576 | B31: =D31 -> DJEU0303641 | C31: DWI101IDR | D31: DJEU0303641 | E31: 20310 | F31: KG | G31: EMPTY | H31: OUTBOUND | I31: 20310 | J31: 46068 | K31: 216068 | L31: V278 17 JAN 2026 | M31: 46039 | N31: 97576 | O31: Additional Tank - tidak perlu di naikkan PR | P31: 23000 | Q31: LCT PERMATA 17 VOY 1219 ETD 10032026 | R31: 46091 | S31: REFILL NEW ISOTANK : | T31: =+S31&D31 -> REFILL NEW ISOTANK :DJEU0303641
A32: =TRIM(N32) -> 97716 | B32: =D32 -> DJEU0303889 | C32: DWI101IDR | D32: DJEU0303889 | E32: 21350 | F32: KG | G32: STOP REFILL | H32: VENDOR | I32: 21350 | J32: 16-24 Feb 2026 | K32: 216350 | L32: V277 02 JAN 2026 | M32: 46024 | N32: 97716 | O32: Additional Tank - tidak perlu di naikkan PR | P32: 23000 | Q32: LCT PERMATA 17 VOY 1219 ETD 10032026 | R32: 46091 | S32: REFILL NEW ISOTANK : | T32: =+S32&D32 -> REFILL NEW ISOTANK :DJEU0303889
A33: =TRIM(N33) -> 97717 | B33: =D33 -> DJEU0303894 | C33: DWI101IDR | D33: DJEU0303894 | E33: 21370 | F33: KG | G33: EMPTY | H33: OUTBOUND | I33: 21370 | J33: 16-24 Feb 2026 | K33: 216350 | L33: V277 02 JAN 2026 | M33: 46024 | N33: 97717 | O33: 99437 | P33: 23000 | Q33: LCT PERMATA 17 VOY 1219 ETD 10032026 | R33: 46091 | S33: REFILL NEW ISOTANK : | T33: =+S33&D33 -> REFILL NEW ISOTANK :DJEU0303894
A34: =TRIM(N34) -> 97663 | B34: =D34 -> DJEU0303786 | C34: DWI101IDR | D34: DJEU0303786 | E34: 21200 | F34: KG | G34: EMPTY | H34: OUTBOUND | I34: 21200 | J34: 16-24 Feb 2026 | K34: 216350 | L34: V279 30 JAN 2026 | M34: 46052 | N34: 97663 | O34: 99441 | P34: 23000 | Q34: LCT P17 VOY 1220 ETD 18032026 | R34: 46099 | S34: REFILL NEW ISOTANK : | T34: =+S34&D34 -> REFILL NEW ISOTANK :DJEU0303786
A35: =TRIM(N35) -> 96654 | B35: =D35 -> SJIU2422675 | C35: ADI106IDR | D35: SJIU2422675 | E35: 28200 | F35: KG | G35: EMPTY | H35: OUTBOUND | I35: 27000 | J35: 45716 | K35: 216425 | L35: V278 17 JAN 2026 | M35: 46039 | N35: 96654 | O35: Additional Tank - tidak perlu di naikkan PR | P35: 23000 | Q35: LCT PERMATA 17 VOY 1219 ETD 10032026 | R35: 46091 | S35: REFILL NEW ISOTANK : | T35: =+S35&D35 -> REFILL NEW ISOTANK :SJIU2422675
A36: =TRIM(N36) -> 96654 | B36: =D36 -> SJIU2422680 | C36: ADI106IDR | D36: SJIU2422680 | E36: 28200 | F36: KG | G36: EMPTY | H36: OUTBOUND | I36: 27000 | J36: 46087 | K36: 216561 | L36: V278 17 JAN 2026 | M36: 46039 | N36: 96654 | O36: Additional Tank - tidak perlu di naikkan PR | P36: 23000 | Q36: LCT PERMATA 17 VOY 1219 ETD 10032026 | R36: 46091 | S36: REFILL NEW ISOTANK : | T36: =+S36&D36 -> REFILL NEW ISOTANK :SJIU2422680
A37: =TRIM(N37) -> 97658 | B37: =D37 -> DJEU0303600 | C37: DWI101IDR | D37: DJEU0303600 | E37: 21390 | F37: KG | G37: STOP REFILL | H37: VENDOR | I37: 21390 | J37: 46087 | K37: 216561 | L37: V278 17 JAN 2026 | M37: 46039 | N37: 97658 | Q37: LCT P17 VOY 1221 ETD 03042026 | S37: REFILL NEW ISOTANK : | T37: =+S37&D37 -> REFILL NEW ISOTANK :DJEU0303600
A38: =TRIM(N38) -> 96093 | B38: =D38 -> SJIU2001260 | C38: ROL100IDR | D38: SJIU2001260 | E38: 20730 | F38: KG | G38: EMPTY | H38: OUTBOUND | I38: =E38 -> 20730 | J38: 46095 | K38: 216738 | L38: V279 30 JAN 2026 | M38: 46052 | N38: 96093 | O38: 99395 | P38: 23000 | Q38: LCT P17 VOY 1221 ETD 03042026 | R38: 46115 | S38: REFILL NEW ISOTANK : | T38: =+S38&D38 -> REFILL NEW ISOTANK :SJIU2001260
A39: =TRIM(N39) -> 97660 | B39: =D39 -> DJEU0303702 | C39: DWI101IDR | D39: DJEU0303702 | E39: 21580 | F39: KG | G39: EMPTY | H39: OUTBOUND | I39: =E39 -> 21580 | J39: 46089 | K39: 216617 | L39: V278 17 JAN 2026 | M39: 46039 | N39: 97660 | O39: 99404 | P39: 23000 | Q39: LCT P17 VOY 1221 ETD 03042026 | R39: 46115 | S39: REFILL NEW ISOTANK : | T39: =+S39&D39 -> REFILL NEW ISOTANK :DJEU0303702
A40: =TRIM(N40) -> 97662 | B40: =D40 -> NTTU1752780 | C40: DWI101IDR | D40: NTTU1752780 | E40: 21370 | F40: KG | G40: EMPTY | H40: OUTBOUND | I40: =E40 -> 21370 | J40: 46089 | K40: 216617 | L40: V278 17 JAN 2026 | M40: 46039 | N40: 97662 | O40: 99399 | P40: 23000 | Q40: LCT P17 VOY 1221 ETD 03042026 | R40: 46115 | S40: REFILL NEW ISOTANK : | T40: =+S40&D40 -> REFILL NEW ISOTANK :NTTU1752780
...

Sheet MASTER
A1: OUTBOUND | E1: FULL
A2: WAREHOUSE | E2: EMPTY
A3: INBOUND - SUB KOE | E3: INSTALL
A4: INBOUND - HUB SUB | E4: STOP REFILL
A5: 25KT
A6: VENDOR
A7: INBOUND- KOE WTR

Sheet REKAP ACID TO PR
F1: 6823-03-114225
B2: PR/PO REFILL ACID OUTBOUND
B3: 6823-03-114225 | C3: 6823-03-114225
A4: Status | B4: TYPE | C4: Vendor | D4: PR | E4: Qty | F4: NOMOR ISO | G4: REMARKS | H4: TANK ID | I4: CM OUT | J4: Next Approval
B5: ACID | C5: ADIMITRA PRIMA LESTARI, PT | D5: PANI (NO REFILL) | E5: PANI (NO REFILL) | F5: SJIU2522993 | G5: LCT PERMATA 17 Voy 1215 ETD 03012026 | K5: REFILL NEW ISOTANK : | L5: =+K5&F5 -> REFILL NEW ISOTANK :SJIU2522993
B6: ACID | C6: ADIMITRA PRIMA LESTARI, PT | D6: PANI (NO REFILL) | E6: PANI (NO REFILL) | F6: SJIU2522972 | G6: LCT PERMATA 17 Voy 1215 ETD 03012026 | K6: REFILL NEW ISOTANK : | L6: =+K6&F6 -> REFILL NEW ISOTANK :SJIU2522972
B7: ACID | C7: ADIMITRA PRIMA LESTARI, PT | D7: PANI (NO REFILL) | E7: PANI (NO REFILL) | F7: SJIU2522967 | G7: LCT PERMATA 17 Voy 1215 ETD 03012026 | K7: REFILL NEW ISOTANK : | L7: =+K7&F7 -> REFILL NEW ISOTANK :SJIU2522967
B8: ACID | C8: ROL100IDR | D8: 98131 | E8: 23000 | F8: NTTU1753765 | G8: LCT PERMATA 17 Voy 1215 ETD 03012026 | K8: REFILL NEW ISOTANK : | L8: =+K8&F8 -> REFILL NEW ISOTANK :NTTU1753765
B9: ACID | C9: ADIMITRA PRIMA LESTARI, PT | D9: PANI (NO REFILL) | E9: PANI (NO REFILL) | F9: SJIU2422612 | G9: LCT PERMATA 17 Voy 1216 ETD 23012026 | K9: REFILL NEW ISOTANK : | L9: =+K9&F9 -> REFILL NEW ISOTANK :SJIU2422612
B10: ACID | C10: ADIMITRA PRIMA LESTARI, PT | D10: PANI (NO REFILL) | E10: PANI (NO REFILL) | F10: SJIU2422628 | G10: LCT PERMATA 17 Voy 1216 ETD 23012026 | K10: REFILL NEW ISOTANK : | L10: =+K10&F10 -> REFILL NEW ISOTANK :SJIU2422628
B11: ACID | C11: DWI101IDR | D11: 98321 | E11: 23000 | F11: DJEU0303636 | G11: LCT PERMATA 17 Voy 1216 ETD 23012026 | K11: REFILL NEW ISOTANK : | L11: =+K11&F11 -> REFILL NEW ISOTANK :DJEU0303636
B12: ACID | C12: ROL100IDR | D12: 98322 | E12: 23000 | F12: NTTU1753739 | G12: LCT PERMATA 17 Voy 1216 ETD 23012026 | K12: REFILL NEW ISOTANK : | L12: =+K12&F12 -> REFILL NEW ISOTANK :NTTU1753739
B13: ACID | C13: ROL100IDR | D13: 98323 | E13: 23000 | F13: NTTU1753702 | G13: LCT PERMATA 17 Voy 1216 ETD 23012026 | K13: REFILL NEW ISOTANK : | L13: =+K13&F13 -> REFILL NEW ISOTANK :NTTU1753702
B14: ACID | C14: DWI101IDR | D14: 98324 | E14: 23000 | F14: NTTU1752748 | G14: LCT PERMATA 17 Voy 1216 ETD 23012026 | K14: REFILL NEW ISOTANK : | L14: =+K14&F14 -> REFILL NEW ISOTANK :NTTU1752748
B15: ACID | C15: DWI101IDR | D15: 98325 | E15: 23000 | F15: DJEU0303810 | G15: LCT PERMATA 17 Voy 1216 ETD 23012026 | K15: REFILL NEW ISOTANK : | L15: =+K15&F15 -> REFILL NEW ISOTANK :DJEU0303810
B16: ACID | C16: DWI101IDR | D16: 98326 | E16: 23000 | F16: DJEU0303699 | G16: LCT PERMATA 17 Voy 1216 ETD 23012026 | K16: REFILL NEW ISOTANK : | L16: =+K16&F16 -> REFILL NEW ISOTANK :DJEU0303699
B17: ACID | C17: DWI101IDR | D17: 98985 | E17: 23000 | F17: DJEU0303718 | G17: LCT PERMATA 17 Voy 1216 ETD 23012026 | K17: REFILL NEW ISOTANK : | L17: =+K17&F17 -> REFILL NEW ISOTANK :DJEU0303718
B18: ACID | C18: DWI101IDR | D18: 98328 | E18: 23000 | F18: DJEU0303791 | G18: LCT PERMATA 17 Voy 1216 ETD 23012026 | K18: REFILL NEW ISOTANK : | L18: =+K18&F18 -> REFILL NEW ISOTANK :DJEU0303791
B19: ACID | C19: DWI101IDR | D19: 98986 | E19: 23000 | F19: DJEU0303826 | G19: LCT PERMATA 17 Voy 1216 ETD 23012026 | K19: REFILL NEW ISOTANK : | L19: =+K19&F19 -> REFILL NEW ISOTANK :DJEU0303826
B20: ACID | C20: DWI101IDR | D20: 98455 | E20: 23000 | F20: DJEU0303765 | G20: LCT PERMATA 17 Voy 1217 ETD 03012026 | K20: REFILL NEW ISOTANK : | L20: =+K20&F20 -> REFILL NEW ISOTANK :DJEU0303765
B21: ACID | C21: DWI101IDR | D21: 98456 | E21: 23000 | F21: NTTU1752795 | G21: LCT PERMATA 17 Voy 1217 ETD 03012026 | K21: REFILL NEW ISOTANK : | L21: =+K21&F21 -> REFILL NEW ISOTANK :NTTU1752795
B22: ACID | C22: DWI101IDR | D22: 98457 | E22: 23000 | F22: DJEU0303750 | G22: LCT PERMATA 17 Voy 1217 ETD 03012026 | K22: REFILL NEW ISOTANK : | L22: =+K22&F22 -> REFILL NEW ISOTANK :DJEU0303750
B23: ACID | C23: DWI101IDR | D23: 98458 | E23: 23000 | F23: NTTU1752711 | G23: LCT PERMATA 17 Voy 1217 ETD 03012026 | K23: REFILL NEW ISOTANK : | L23: =+K23&F23 -> REFILL NEW ISOTANK :NTTU1752711
B24: ACID | C24: DWI101IDR | D24: 98987 | E24: 23000 | F24: NTTU1752671 | G24: LCT PERMATA 17 Voy 1218 ETD 25022026 | K24: REFILL NEW ISOTANK : | L24: =+K24&F24 -> REFILL NEW ISOTANK :NTTU1752671 | P24: NTTU1752687
B25: ACID | C25: DWI101IDR | D25: 98988 | E25: 23000 | F25: NTTU1752692 | G25: LCT PERMATA 17 Voy 1218 ETD 25022026 | K25: REFILL NEW ISOTANK : | L25: =+K25&F25 -> REFILL NEW ISOTANK :NTTU1752692 | P25: DJEU0303739
B26: ACID | C26: ADIMITRA PRIMA LESTARI, PT | D26: PANI (NO REFILL) | E26: PANI (NO REFILL) | F26: SJIU2422633 | G26: LCT PERMATA 17 Voy 1218 ETD 25022026 | K26: REFILL NEW ISOTANK : | L26: =+K26&F26 -> REFILL NEW ISOTANK :SJIU2422633 | P26: NTTU1752753
B27: ACID | C27: ADIMITRA PRIMA LESTARI, PT | D27: PANI (NO REFILL) | E27: PANI (NO REFILL) | F27: SJIU2422649 | G27: LCT PERMATA 17 Voy 1218 ETD 25022026 | K27: REFILL NEW ISOTANK : | L27: =+K27&F27 -> REFILL NEW ISOTANK :SJIU2422649 | P27: DJEU0303786
B28: ACID | C28: ADIMITRA PRIMA LESTARI, PT | D28: PANI (NO REFILL) | E28: PANI (NO REFILL) | F28: SJIU2422660 | G28: LCT PERMATA 17 Voy 1218 ETD 25022026 | K28: REFILL NEW ISOTANK : | L28: =+K28&F28 -> REFILL NEW ISOTANK :SJIU2422660 | P28: DJEU0303770
B29: ACID | C29: DWI101IDR | D29: 99398 | E29: 23000 | F29: DJEU0303600 | G29: LCT P17 VOY 1221 ETD 13042026 | K29: REFILL NEW ISOTANK : | L29: =+K29&F29 -> REFILL NEW ISOTANK :DJEU0303600
B30: ACID | C30: ROL100IDR | D30: 99395 | E30: 23000 | F30: SJIU2001260 | G30: LCT P17 VOY 1221 ETD 13042026 | K30: REFILL NEW ISOTANK : | L30: =+K30&F30 -> REFILL NEW ISOTANK :SJIU2001260
B31: ACID | C31: DWI101IDR | D31: 99404 | E31: 23000 | F31: DJEU0303702 | G31: LCT P17 VOY 1221 ETD 13042026 | K31: REFILL NEW ISOTANK : | L31: =+K31&F31 -> REFILL NEW ISOTANK :DJEU0303702
B32: ACID | C32: DWI101IDR | D32: 99399 | E32: 23000 | F32: NTTU1752780 | G32: LCT P17 VOY 1221 ETD 13042026 | K32: REFILL NEW ISOTANK : | L32: =+K32&F32 -> REFILL NEW ISOTANK :NTTU1752780
B33: ACID | C33: ROL100IDR | D33: 99401 | E33: 23000 | F33: SJIU2322017 | G33: LCT P17 VOY 1221 ETD 13042026 | K33: REFILL NEW ISOTANK : | L33: =+K33&F33 -> REFILL NEW ISOTANK :SJIU2322017
B34: ACID | C34: ROL100IDR | D34: 99402 | E34: 23000 | F34: SJIU2221557 | G34: LCT P17 VOY 1221 ETD 13042026 | K34: REFILL NEW ISOTANK : | L34: =+K34&F34 -> REFILL NEW ISOTANK :SJIU2221557
B35: ACID | C35: ROL100IDR | D35: 99403 | E35: 23000 | F35: SJIU2221726 | G35: LCT P17 VOY 1221 ETD 13042026 | K35: REFILL NEW ISOTANK : | L35: =+K35&F35 -> REFILL NEW ISOTANK :SJIU2221726
B36: ACID | C36: DWI101IDR | D36: 99400 | E36: 23000 | F36: DJEU0303662 | G36: LCT P17 VOY 1221 ETD 13042026 | K36: REFILL NEW ISOTANK : | L36: =+K36&F36 -> REFILL NEW ISOTANK :DJEU0303662
B37: ACID | C37: ROL100IDR | D37: 99397 | E37: 23000 | F37: NTTU1753723 | G37: LCT P17 VOY 1221 ETD 13042026 | K37: REFILL NEW ISOTANK : | L37: =+K37&F37 -> REFILL NEW ISOTANK :NTTU1753723
B38: ACID | C38: ROL100IDR | D38: 99396 | E38: 23000 | F38: SJIU2322022 | G38: LCT P17 VOY 1221 ETD 13042026 | K38: REFILL NEW ISOTANK : | L38: =+K38&F38 -> REFILL NEW ISOTANK :SJIU2322022
A39: SOC DJE | B39: ACID | C39: DWI101IDR | D39: 99435 | E39: 23000 | F39: DJEU0303873 | G39: LCT P17 VOY 1220 ETD 18032026 | K39: REFILL NEW ISOTANK : | L39: =+K39&F39 -> REFILL NEW ISOTANK :DJEU0303873
A40: SOC DJE | B40: ACID | C40: DWI101IDR | D40: 99436 | E40: 23000 | F40: NTTU1752727 | G40: LCT P17 VOY 1220 ETD 18032026 | K40: REFILL NEW ISOTANK : | L40: =+K40&F40 -> REFILL NEW ISOTANK :NTTU1752727
...

Sheet mei
A1: Vendor | B1: PO | D1: No. Isotank | E1: Qty | F1: Remaks | I1: Qty On Site | K1: Qty Empty On Site | M1: Outbound ( Koe - Sub) | O1: Outbound HUB | Q1: Inbound ( KOE-SUB) | S1: Inbound ( SUB-KOE) | U1: Total Supply | W1: Kekurangan
A2: Dwijaya | B2: 99615 | C2: April | D2: DJEU0303868 | E2: 20000 | I2: QTY Isotank | J2: Qty Kg | K2: QTY Isotank | L2: Qty Kg | M2: QTY Isotank | N2: Qty Kg | O2: QTY Isotank | P2: Qty Kg | Q2: QTY Isotank | R2: Qty Kg | S2: QTY Isotank | T2: Qty Kg | U2: QTY Isotank | V2: Qty Kg | W2: QTY Isotank | X2: Qty Kg
B3: 99623 | C3: April | D3: DJEU0303805 | E3: 20000 | H3: ENERGI JAYA INOVASI PT | I3: 0 | K3: 0 | U3: 2 | V3: 500000 | W3: =U3-S3-Q3 -> 2 | X3: =V3-T3-R3 -> 500000
B4: 99624 | C4: April | D4: DJEU0303908 | E4: 20000 | H4: DWI JAYA EKAPRIMA, PT | I4: 7 | K4: 4 | M4: 9 | N4: =M4*20500 -> 184500 | O4: 7 | P4: =O4*20500 -> 143500 | Q4: 3 | R4: 63230 | S4: 1 | T4: 85930 | U4: 9 | V4: 180000 | W4: =U4-S4-Q4 -> 5 | X4: =V4-T4-R4 -> 30840
B5: 99625 | C5: April | D5: DJEU0303852 | E5: 20000 | H5: ROLIMEX | I5: 5 | K5: 0 | M5: 4 | N5: =20500*4 -> 82000 | O5: 8 | P5: =O5*20500 -> 164000 | Q5: 5 | R5: 102790 | S5: 3 | T5: 61800 | U5: 15 | V5: 310000 | W5: =U5-S5-Q5 -> 7 | X5: =V5-T5-R5 -> 145410
